2021-07-16 12:30:04.630 database_manager:661 [INFO] [MainThread 4671135232] Starting dbm in dbm starter
2021-07-16 12:30:04.631 database_manager:523 [INFO] [Monitoring-migrate-priority 123145426808832] Starting processing for queue priority
2021-07-16 12:30:04.632 database_manager:523 [INFO] [Monitoring-migrate-node 123145443598336] Starting processing for queue node
2021-07-16 12:30:04.633 database_manager:523 [INFO] [Monitoring-migrate-block 123145460387840] Starting processing for queue block
2021-07-16 12:30:04.634 database_manager:523 [INFO] [Monitoring-migrate-resource 123145477177344] Starting processing for queue resource
2021-07-16 12:30:05.158 database_manager:604 [ERROR] [MainThread 4671135232] Got exception when trying to insert to table task
Traceback (most recent call last):
  File "/opt/anaconda3/lib/python3.8/site-packages/sqlalchemy/engine/base.py", line 1276, in _execute_context
    self.dialect.do_execute(
  File "/opt/anaconda3/lib/python3.8/site-packages/sqlalchemy/engine/default.py", line 608, in do_execute
    cursor.execute(statement, parameters)
sqlite3.IntegrityError: NOT NULL constraint failed: task.task_fail_cost

The above exception was the direct cause of the following exception:

Traceback (most recent call last):
  File "/opt/anaconda3/lib/python3.8/site-packages/parsl/monitoring/db_manager.py", line 589, in _insert
    self.db.insert(table=table, messages=messages)
  File "/opt/anaconda3/lib/python3.8/site-packages/parsl/monitoring/db_manager.py", line 89, in insert
    self.session.bulk_insert_mappings(mapper, mappings)
  File "/opt/anaconda3/lib/python3.8/site-packages/sqlalchemy/orm/session.py", line 2880, in bulk_insert_mappings
    self._bulk_save_mappings(
  File "/opt/anaconda3/lib/python3.8/site-packages/sqlalchemy/orm/session.py", line 2979, in _bulk_save_mappings
    transaction.rollback(_capture_exception=True)
  File "/opt/anaconda3/lib/python3.8/site-packages/sqlalchemy/util/langhelpers.py", line 68, in __exit__
    compat.raise_(
  File "/opt/anaconda3/lib/python3.8/site-packages/sqlalchemy/util/compat.py", line 182, in raise_
    raise exception
  File "/opt/anaconda3/lib/python3.8/site-packages/sqlalchemy/orm/session.py", line 2967, in _bulk_save_mappings
    persistence._bulk_insert(
  File "/opt/anaconda3/lib/python3.8/site-packages/sqlalchemy/orm/persistence.py", line 95, in _bulk_insert
    _emit_insert_statements(
  File "/opt/anaconda3/lib/python3.8/site-packages/sqlalchemy/orm/persistence.py", line 1083, in _emit_insert_statements
    c = cached_connections[connection].execute(statement, multiparams)
  File "/opt/anaconda3/lib/python3.8/site-packages/sqlalchemy/engine/base.py", line 1011, in execute
    return meth(self, multiparams, params)
  File "/opt/anaconda3/lib/python3.8/site-packages/sqlalchemy/sql/elements.py", line 298, in _execute_on_connection
    return connection._execute_clauseelement(self, multiparams, params)
  File "/opt/anaconda3/lib/python3.8/site-packages/sqlalchemy/engine/base.py", line 1124, in _execute_clauseelement
    ret = self._execute_context(
  File "/opt/anaconda3/lib/python3.8/site-packages/sqlalchemy/engine/base.py", line 1316, in _execute_context
    self._handle_dbapi_exception(
  File "/opt/anaconda3/lib/python3.8/site-packages/sqlalchemy/engine/base.py", line 1510, in _handle_dbapi_exception
    util.raise_(
  File "/opt/anaconda3/lib/python3.8/site-packages/sqlalchemy/util/compat.py", line 182, in raise_
    raise exception
  File "/opt/anaconda3/lib/python3.8/site-packages/sqlalchemy/engine/base.py", line 1276, in _execute_context
    self.dialect.do_execute(
  File "/opt/anaconda3/lib/python3.8/site-packages/sqlalchemy/engine/default.py", line 608, in do_execute
    cursor.execute(statement, parameters)
sqlalchemy.exc.IntegrityError: (sqlite3.IntegrityError) NOT NULL constraint failed: task.task_fail_cost
[SQL: INSERT INTO task (task_id, run_id, task_depends, task_func_name, task_memoize, task_inputs, task_outputs, task_time_invoked, task_fail_count) VALUES (?, ?, ?, ?, ?, ?, ?, ?, ?)]
[parameters: (0, '806adb91-bf06-458b-bdfa-f3577af242f3', '', 'app_F', False, 'None', 'None', '2021-07-16 12:30:04.778685', 0)]
(Background on this error at: http://sqlalche.me/e/13/gkpj)
2021-07-16 12:30:05.168 database_manager:578 [ERROR] [MainThread 4671135232] Got exception when trying to update table task
Traceback (most recent call last):
  File "/opt/anaconda3/lib/python3.8/site-packages/parsl/monitoring/db_manager.py", line 559, in _update
    self.db.update(table=table, columns=columns, messages=messages)
  File "/opt/anaconda3/lib/python3.8/site-packages/parsl/monitoring/db_manager.py", line 82, in update
    self.session.bulk_update_mappings(mapper, mappings)
  File "/opt/anaconda3/lib/python3.8/site-packages/sqlalchemy/orm/session.py", line 2939, in bulk_update_mappings
    self._bulk_save_mappings(
  File "/opt/anaconda3/lib/python3.8/site-packages/sqlalchemy/orm/session.py", line 2979, in _bulk_save_mappings
    transaction.rollback(_capture_exception=True)
  File "/opt/anaconda3/lib/python3.8/site-packages/sqlalchemy/util/langhelpers.py", line 68, in __exit__
    compat.raise_(
  File "/opt/anaconda3/lib/python3.8/site-packages/sqlalchemy/util/compat.py", line 182, in raise_
    raise exception
  File "/opt/anaconda3/lib/python3.8/site-packages/sqlalchemy/orm/session.py", line 2959, in _bulk_save_mappings
    persistence._bulk_update(
  File "/opt/anaconda3/lib/python3.8/site-packages/sqlalchemy/orm/persistence.py", line 173, in _bulk_update
    _emit_update_statements(
  File "/opt/anaconda3/lib/python3.8/site-packages/sqlalchemy/orm/persistence.py", line 1025, in _emit_update_statements
    raise orm_exc.StaleDataError(
sqlalchemy.orm.exc.StaleDataError: UPDATE statement on table 'task' expected to update 1 row(s); 0 were matched.
2021-07-16 12:30:07.340 database_manager:604 [ERROR] [MainThread 4671135232] Got exception when trying to insert to table task
Traceback (most recent call last):
  File "/opt/anaconda3/lib/python3.8/site-packages/sqlalchemy/engine/base.py", line 1256, in _execute_context
    self.dialect.do_executemany(
  File "/opt/anaconda3/lib/python3.8/site-packages/sqlalchemy/engine/default.py", line 605, in do_executemany
    cursor.executemany(statement, parameters)
sqlite3.IntegrityError: NOT NULL constraint failed: task.task_fail_cost

The above exception was the direct cause of the following exception:

Traceback (most recent call last):
  File "/opt/anaconda3/lib/python3.8/site-packages/parsl/monitoring/db_manager.py", line 589, in _insert
    self.db.insert(table=table, messages=messages)
  File "/opt/anaconda3/lib/python3.8/site-packages/parsl/monitoring/db_manager.py", line 89, in insert
    self.session.bulk_insert_mappings(mapper, mappings)
  File "/opt/anaconda3/lib/python3.8/site-packages/sqlalchemy/orm/session.py", line 2880, in bulk_insert_mappings
    self._bulk_save_mappings(
  File "/opt/anaconda3/lib/python3.8/site-packages/sqlalchemy/orm/session.py", line 2979, in _bulk_save_mappings
    transaction.rollback(_capture_exception=True)
  File "/opt/anaconda3/lib/python3.8/site-packages/sqlalchemy/util/langhelpers.py", line 68, in __exit__
    compat.raise_(
  File "/opt/anaconda3/lib/python3.8/site-packages/sqlalchemy/util/compat.py", line 182, in raise_
    raise exception
  File "/opt/anaconda3/lib/python3.8/site-packages/sqlalchemy/orm/session.py", line 2967, in _bulk_save_mappings
    persistence._bulk_insert(
  File "/opt/anaconda3/lib/python3.8/site-packages/sqlalchemy/orm/persistence.py", line 95, in _bulk_insert
    _emit_insert_statements(
  File "/opt/anaconda3/lib/python3.8/site-packages/sqlalchemy/orm/persistence.py", line 1083, in _emit_insert_statements
    c = cached_connections[connection].execute(statement, multiparams)
  File "/opt/anaconda3/lib/python3.8/site-packages/sqlalchemy/engine/base.py", line 1011, in execute
    return meth(self, multiparams, params)
  File "/opt/anaconda3/lib/python3.8/site-packages/sqlalchemy/sql/elements.py", line 298, in _execute_on_connection
    return connection._execute_clauseelement(self, multiparams, params)
  File "/opt/anaconda3/lib/python3.8/site-packages/sqlalchemy/engine/base.py", line 1124, in _execute_clauseelement
    ret = self._execute_context(
  File "/opt/anaconda3/lib/python3.8/site-packages/sqlalchemy/engine/base.py", line 1316, in _execute_context
    self._handle_dbapi_exception(
  File "/opt/anaconda3/lib/python3.8/site-packages/sqlalchemy/engine/base.py", line 1510, in _handle_dbapi_exception
    util.raise_(
  File "/opt/anaconda3/lib/python3.8/site-packages/sqlalchemy/util/compat.py", line 182, in raise_
    raise exception
  File "/opt/anaconda3/lib/python3.8/site-packages/sqlalchemy/engine/base.py", line 1256, in _execute_context
    self.dialect.do_executemany(
  File "/opt/anaconda3/lib/python3.8/site-packages/sqlalchemy/engine/default.py", line 605, in do_executemany
    cursor.executemany(statement, parameters)
sqlalchemy.exc.IntegrityError: (sqlite3.IntegrityError) NOT NULL constraint failed: task.task_fail_cost
[SQL: INSERT INTO task (task_id, run_id, task_depends, task_func_name, task_memoize, task_inputs, task_outputs, task_time_invoked, task_fail_count) VALUES (?, ?, ?, ?, ?, ?, ?, ?, ?)]
[parameters: ((1, '806adb91-bf06-458b-bdfa-f3577af242f3', '', 'app_A', False, 'None', 'None', '2021-07-16 12:30:06.923293', 0), (2, '806adb91-bf06-458b-bdfa-f3577af242f3', '', 'app_B', False, 'None', 'None', '2021-07-16 12:30:06.932226', 0), (3, '806adb91-bf06-458b-bdfa-f3577af242f3', '1,2', 'app_C', False, 'None', 'None', '2021-07-16 12:30:06.936411', 0), (4, '806adb91-bf06-458b-bdfa-f3577af242f3', '3', 'app_D', False, 'None', 'None', '2021-07-16 12:30:06.937434', 0), (5, '806adb91-bf06-458b-bdfa-f3577af242f3', '4', 'app_E', False, 'None', 'None', '2021-07-16 12:30:06.938336', 0))]
(Background on this error at: http://sqlalche.me/e/13/gkpj)
2021-07-16 12:30:07.345 database_manager:578 [ERROR] [MainThread 4671135232] Got exception when trying to update table task
Traceback (most recent call last):
  File "/opt/anaconda3/lib/python3.8/site-packages/parsl/monitoring/db_manager.py", line 559, in _update
    self.db.update(table=table, columns=columns, messages=messages)
  File "/opt/anaconda3/lib/python3.8/site-packages/parsl/monitoring/db_manager.py", line 82, in update
    self.session.bulk_update_mappings(mapper, mappings)
  File "/opt/anaconda3/lib/python3.8/site-packages/sqlalchemy/orm/session.py", line 2939, in bulk_update_mappings
    self._bulk_save_mappings(
  File "/opt/anaconda3/lib/python3.8/site-packages/sqlalchemy/orm/session.py", line 2979, in _bulk_save_mappings
    transaction.rollback(_capture_exception=True)
  File "/opt/anaconda3/lib/python3.8/site-packages/sqlalchemy/util/langhelpers.py", line 68, in __exit__
    compat.raise_(
  File "/opt/anaconda3/lib/python3.8/site-packages/sqlalchemy/util/compat.py", line 182, in raise_
    raise exception
  File "/opt/anaconda3/lib/python3.8/site-packages/sqlalchemy/orm/session.py", line 2959, in _bulk_save_mappings
    persistence._bulk_update(
  File "/opt/anaconda3/lib/python3.8/site-packages/sqlalchemy/orm/persistence.py", line 173, in _bulk_update
    _emit_update_statements(
  File "/opt/anaconda3/lib/python3.8/site-packages/sqlalchemy/orm/persistence.py", line 1025, in _emit_update_statements
    raise orm_exc.StaleDataError(
sqlalchemy.orm.exc.StaleDataError: UPDATE statement on table 'task' expected to update 6 row(s); 0 were matched.
2021-07-16 12:30:08.131 database_manager:604 [ERROR] [MainThread 4671135232] Got exception when trying to insert to table task
Traceback (most recent call last):
  File "/opt/anaconda3/lib/python3.8/site-packages/sqlalchemy/engine/base.py", line 1256, in _execute_context
    self.dialect.do_executemany(
  File "/opt/anaconda3/lib/python3.8/site-packages/sqlalchemy/engine/default.py", line 605, in do_executemany
    cursor.executemany(statement, parameters)
sqlite3.IntegrityError: NOT NULL constraint failed: task.task_fail_cost

The above exception was the direct cause of the following exception:

Traceback (most recent call last):
  File "/opt/anaconda3/lib/python3.8/site-packages/parsl/monitoring/db_manager.py", line 589, in _insert
    self.db.insert(table=table, messages=messages)
  File "/opt/anaconda3/lib/python3.8/site-packages/parsl/monitoring/db_manager.py", line 89, in insert
    self.session.bulk_insert_mappings(mapper, mappings)
  File "/opt/anaconda3/lib/python3.8/site-packages/sqlalchemy/orm/session.py", line 2880, in bulk_insert_mappings
    self._bulk_save_mappings(
  File "/opt/anaconda3/lib/python3.8/site-packages/sqlalchemy/orm/session.py", line 2979, in _bulk_save_mappings
    transaction.rollback(_capture_exception=True)
  File "/opt/anaconda3/lib/python3.8/site-packages/sqlalchemy/util/langhelpers.py", line 68, in __exit__
    compat.raise_(
  File "/opt/anaconda3/lib/python3.8/site-packages/sqlalchemy/util/compat.py", line 182, in raise_
    raise exception
  File "/opt/anaconda3/lib/python3.8/site-packages/sqlalchemy/orm/session.py", line 2967, in _bulk_save_mappings
    persistence._bulk_insert(
  File "/opt/anaconda3/lib/python3.8/site-packages/sqlalchemy/orm/persistence.py", line 95, in _bulk_insert
    _emit_insert_statements(
  File "/opt/anaconda3/lib/python3.8/site-packages/sqlalchemy/orm/persistence.py", line 1083, in _emit_insert_statements
    c = cached_connections[connection].execute(statement, multiparams)
  File "/opt/anaconda3/lib/python3.8/site-packages/sqlalchemy/engine/base.py", line 1011, in execute
    return meth(self, multiparams, params)
  File "/opt/anaconda3/lib/python3.8/site-packages/sqlalchemy/sql/elements.py", line 298, in _execute_on_connection
    return connection._execute_clauseelement(self, multiparams, params)
  File "/opt/anaconda3/lib/python3.8/site-packages/sqlalchemy/engine/base.py", line 1124, in _execute_clauseelement
    ret = self._execute_context(
  File "/opt/anaconda3/lib/python3.8/site-packages/sqlalchemy/engine/base.py", line 1316, in _execute_context
    self._handle_dbapi_exception(
  File "/opt/anaconda3/lib/python3.8/site-packages/sqlalchemy/engine/base.py", line 1510, in _handle_dbapi_exception
    util.raise_(
  File "/opt/anaconda3/lib/python3.8/site-packages/sqlalchemy/util/compat.py", line 182, in raise_
    raise exception
  File "/opt/anaconda3/lib/python3.8/site-packages/sqlalchemy/engine/base.py", line 1256, in _execute_context
    self.dialect.do_executemany(
  File "/opt/anaconda3/lib/python3.8/site-packages/sqlalchemy/engine/default.py", line 605, in do_executemany
    cursor.executemany(statement, parameters)
sqlalchemy.exc.IntegrityError: (sqlite3.IntegrityError) NOT NULL constraint failed: task.task_fail_cost
[SQL: INSERT INTO task (task_id, run_id, task_depends, task_func_name, task_memoize, task_inputs, task_outputs, task_time_invoked, task_fail_count) VALUES (?, ?, ?, ?, ?, ?, ?, ?, ?)]
[parameters: ((6, '806adb91-bf06-458b-bdfa-f3577af242f3', '', 'app_A', False, 'None', 'None', '2021-07-16 12:30:07.762290', 0), (7, '806adb91-bf06-458b-bdfa-f3577af242f3', '', 'app_B', False, 'None', 'None', '2021-07-16 12:30:07.768146', 0), (8, '806adb91-bf06-458b-bdfa-f3577af242f3', '6,7', 'app_C', False, 'None', 'None', '2021-07-16 12:30:07.770932', 0), (9, '806adb91-bf06-458b-bdfa-f3577af242f3', '8', 'app_D', False, 'None', 'None', '2021-07-16 12:30:07.771708', 0), (10, '806adb91-bf06-458b-bdfa-f3577af242f3', '9', 'app_E', False, 'None', 'None', '2021-07-16 12:30:07.772422', 0))]
(Background on this error at: http://sqlalche.me/e/13/gkpj)
2021-07-16 12:30:08.136 database_manager:578 [ERROR] [MainThread 4671135232] Got exception when trying to update table task
Traceback (most recent call last):
  File "/opt/anaconda3/lib/python3.8/site-packages/parsl/monitoring/db_manager.py", line 559, in _update
    self.db.update(table=table, columns=columns, messages=messages)
  File "/opt/anaconda3/lib/python3.8/site-packages/parsl/monitoring/db_manager.py", line 82, in update
    self.session.bulk_update_mappings(mapper, mappings)
  File "/opt/anaconda3/lib/python3.8/site-packages/sqlalchemy/orm/session.py", line 2939, in bulk_update_mappings
    self._bulk_save_mappings(
  File "/opt/anaconda3/lib/python3.8/site-packages/sqlalchemy/orm/session.py", line 2979, in _bulk_save_mappings
    transaction.rollback(_capture_exception=True)
  File "/opt/anaconda3/lib/python3.8/site-packages/sqlalchemy/util/langhelpers.py", line 68, in __exit__
    compat.raise_(
  File "/opt/anaconda3/lib/python3.8/site-packages/sqlalchemy/util/compat.py", line 182, in raise_
    raise exception
  File "/opt/anaconda3/lib/python3.8/site-packages/sqlalchemy/orm/session.py", line 2959, in _bulk_save_mappings
    persistence._bulk_update(
  File "/opt/anaconda3/lib/python3.8/site-packages/sqlalchemy/orm/persistence.py", line 173, in _bulk_update
    _emit_update_statements(
  File "/opt/anaconda3/lib/python3.8/site-packages/sqlalchemy/orm/persistence.py", line 1025, in _emit_update_statements
    raise orm_exc.StaleDataError(
sqlalchemy.orm.exc.StaleDataError: UPDATE statement on table 'task' expected to update 10 row(s); 0 were matched.
2021-07-16 12:30:08.573 database_manager:578 [ERROR] [MainThread 4671135232] Got exception when trying to update table task
Traceback (most recent call last):
  File "/opt/anaconda3/lib/python3.8/site-packages/parsl/monitoring/db_manager.py", line 559, in _update
    self.db.update(table=table, columns=columns, messages=messages)
  File "/opt/anaconda3/lib/python3.8/site-packages/parsl/monitoring/db_manager.py", line 82, in update
    self.session.bulk_update_mappings(mapper, mappings)
  File "/opt/anaconda3/lib/python3.8/site-packages/sqlalchemy/orm/session.py", line 2939, in bulk_update_mappings
    self._bulk_save_mappings(
  File "/opt/anaconda3/lib/python3.8/site-packages/sqlalchemy/orm/session.py", line 2979, in _bulk_save_mappings
    transaction.rollback(_capture_exception=True)
  File "/opt/anaconda3/lib/python3.8/site-packages/sqlalchemy/util/langhelpers.py", line 68, in __exit__
    compat.raise_(
  File "/opt/anaconda3/lib/python3.8/site-packages/sqlalchemy/util/compat.py", line 182, in raise_
    raise exception
  File "/opt/anaconda3/lib/python3.8/site-packages/sqlalchemy/orm/session.py", line 2959, in _bulk_save_mappings
    persistence._bulk_update(
  File "/opt/anaconda3/lib/python3.8/site-packages/sqlalchemy/orm/persistence.py", line 173, in _bulk_update
    _emit_update_statements(
  File "/opt/anaconda3/lib/python3.8/site-packages/sqlalchemy/orm/persistence.py", line 1025, in _emit_update_statements
    raise orm_exc.StaleDataError(
sqlalchemy.orm.exc.StaleDataError: UPDATE statement on table 'task' expected to update 4 row(s); 0 were matched.
2021-07-16 12:30:09.054 database_manager:578 [ERROR] [MainThread 4671135232] Got exception when trying to update table task
Traceback (most recent call last):
  File "/opt/anaconda3/lib/python3.8/site-packages/parsl/monitoring/db_manager.py", line 559, in _update
    self.db.update(table=table, columns=columns, messages=messages)
  File "/opt/anaconda3/lib/python3.8/site-packages/parsl/monitoring/db_manager.py", line 82, in update
    self.session.bulk_update_mappings(mapper, mappings)
  File "/opt/anaconda3/lib/python3.8/site-packages/sqlalchemy/orm/session.py", line 2939, in bulk_update_mappings
    self._bulk_save_mappings(
  File "/opt/anaconda3/lib/python3.8/site-packages/sqlalchemy/orm/session.py", line 2979, in _bulk_save_mappings
    transaction.rollback(_capture_exception=True)
  File "/opt/anaconda3/lib/python3.8/site-packages/sqlalchemy/util/langhelpers.py", line 68, in __exit__
    compat.raise_(
  File "/opt/anaconda3/lib/python3.8/site-packages/sqlalchemy/util/compat.py", line 182, in raise_
    raise exception
  File "/opt/anaconda3/lib/python3.8/site-packages/sqlalchemy/orm/session.py", line 2959, in _bulk_save_mappings
    persistence._bulk_update(
  File "/opt/anaconda3/lib/python3.8/site-packages/sqlalchemy/orm/persistence.py", line 173, in _bulk_update
    _emit_update_statements(
  File "/opt/anaconda3/lib/python3.8/site-packages/sqlalchemy/orm/persistence.py", line 1025, in _emit_update_statements
    raise orm_exc.StaleDataError(
sqlalchemy.orm.exc.StaleDataError: UPDATE statement on table 'task' expected to update 1 row(s); 0 were matched.
2021-07-16 12:30:11.709 database_manager:627 [INFO] [Monitoring-migrate-priority 123145426808832] Database Manager cleanup initiated.
2021-07-16 12:30:11.840 database_manager:672 [INFO] [MainThread 4671135232] End of dbm_starter
