2021-07-19 09:00:06.057 database_manager:661 [INFO] [MainThread 4545093120] Starting dbm in dbm starter
2021-07-19 09:00:06.058 database_manager:523 [INFO] [Monitoring-migrate-priority 123145327075328] Starting processing for queue priority
2021-07-19 09:00:06.058 database_manager:523 [INFO] [Monitoring-migrate-node 123145343864832] Starting processing for queue node
2021-07-19 09:00:06.059 database_manager:523 [INFO] [Monitoring-migrate-block 123145360654336] Starting processing for queue block
2021-07-19 09:00:06.060 database_manager:523 [INFO] [Monitoring-migrate-resource 123145377443840] Starting processing for queue resource
2021-07-19 09:00:06.585 database_manager:604 [ERROR] [MainThread 4545093120] Got exception when trying to insert to table task
Traceback (most recent call last):
  File "/opt/anaconda3/lib/python3.8/site-packages/sqlalchemy/engine/base.py", line 1276, in _execute_context
    self.dialect.do_execute(
  File "/opt/anaconda3/lib/python3.8/site-packages/sqlalchemy/engine/default.py", line 608, in do_execute
    cursor.execute(statement, parameters)
sqlite3.IntegrityError: NOT NULL constraint failed: task.task_fail_cost

The above exception was the direct cause of the following exception:

Traceback (most recent call last):
  File "/opt/anaconda3/lib/python3.8/site-packages/parsl/monitoring/db_manager.py", line 589, in _insert
    self.db.insert(table=table, messages=messages)
  File "/opt/anaconda3/lib/python3.8/site-packages/parsl/monitoring/db_manager.py", line 89, in insert
    self.session.bulk_insert_mappings(mapper, mappings)
  File "/opt/anaconda3/lib/python3.8/site-packages/sqlalchemy/orm/session.py", line 2880, in bulk_insert_mappings
    self._bulk_save_mappings(
  File "/opt/anaconda3/lib/python3.8/site-packages/sqlalchemy/orm/session.py", line 2979, in _bulk_save_mappings
    transaction.rollback(_capture_exception=True)
  File "/opt/anaconda3/lib/python3.8/site-packages/sqlalchemy/util/langhelpers.py", line 68, in __exit__
    compat.raise_(
  File "/opt/anaconda3/lib/python3.8/site-packages/sqlalchemy/util/compat.py", line 182, in raise_
    raise exception
  File "/opt/anaconda3/lib/python3.8/site-packages/sqlalchemy/orm/session.py", line 2967, in _bulk_save_mappings
    persistence._bulk_insert(
  File "/opt/anaconda3/lib/python3.8/site-packages/sqlalchemy/orm/persistence.py", line 95, in _bulk_insert
    _emit_insert_statements(
  File "/opt/anaconda3/lib/python3.8/site-packages/sqlalchemy/orm/persistence.py", line 1083, in _emit_insert_statements
    c = cached_connections[connection].execute(statement, multiparams)
  File "/opt/anaconda3/lib/python3.8/site-packages/sqlalchemy/engine/base.py", line 1011, in execute
    return meth(self, multiparams, params)
  File "/opt/anaconda3/lib/python3.8/site-packages/sqlalchemy/sql/elements.py", line 298, in _execute_on_connection
    return connection._execute_clauseelement(self, multiparams, params)
  File "/opt/anaconda3/lib/python3.8/site-packages/sqlalchemy/engine/base.py", line 1124, in _execute_clauseelement
    ret = self._execute_context(
  File "/opt/anaconda3/lib/python3.8/site-packages/sqlalchemy/engine/base.py", line 1316, in _execute_context
    self._handle_dbapi_exception(
  File "/opt/anaconda3/lib/python3.8/site-packages/sqlalchemy/engine/base.py", line 1510, in _handle_dbapi_exception
    util.raise_(
  File "/opt/anaconda3/lib/python3.8/site-packages/sqlalchemy/util/compat.py", line 182, in raise_
    raise exception
  File "/opt/anaconda3/lib/python3.8/site-packages/sqlalchemy/engine/base.py", line 1276, in _execute_context
    self.dialect.do_execute(
  File "/opt/anaconda3/lib/python3.8/site-packages/sqlalchemy/engine/default.py", line 608, in do_execute
    cursor.execute(statement, parameters)
sqlalchemy.exc.IntegrityError: (sqlite3.IntegrityError) NOT NULL constraint failed: task.task_fail_cost
[SQL: INSERT INTO task (task_id, run_id, task_depends, task_func_name, task_memoize, task_inputs, task_outputs, task_time_invoked, task_fail_count) VALUES (?, ?, ?, ?, ?, ?, ?, ?, ?)]
[parameters: (0, '56acd361-53d9-4fc2-a6c5-588f15bc9539', '', 'app_F', False, 'None', 'None', '2021-07-19 09:00:06.213348', 0)]
(Background on this error at: http://sqlalche.me/e/13/gkpj)
2021-07-19 09:00:06.607 database_manager:578 [ERROR] [MainThread 4545093120] Got exception when trying to update table task
Traceback (most recent call last):
  File "/opt/anaconda3/lib/python3.8/site-packages/parsl/monitoring/db_manager.py", line 559, in _update
    self.db.update(table=table, columns=columns, messages=messages)
  File "/opt/anaconda3/lib/python3.8/site-packages/parsl/monitoring/db_manager.py", line 82, in update
    self.session.bulk_update_mappings(mapper, mappings)
  File "/opt/anaconda3/lib/python3.8/site-packages/sqlalchemy/orm/session.py", line 2939, in bulk_update_mappings
    self._bulk_save_mappings(
  File "/opt/anaconda3/lib/python3.8/site-packages/sqlalchemy/orm/session.py", line 2979, in _bulk_save_mappings
    transaction.rollback(_capture_exception=True)
  File "/opt/anaconda3/lib/python3.8/site-packages/sqlalchemy/util/langhelpers.py", line 68, in __exit__
    compat.raise_(
  File "/opt/anaconda3/lib/python3.8/site-packages/sqlalchemy/util/compat.py", line 182, in raise_
    raise exception
  File "/opt/anaconda3/lib/python3.8/site-packages/sqlalchemy/orm/session.py", line 2959, in _bulk_save_mappings
    persistence._bulk_update(
  File "/opt/anaconda3/lib/python3.8/site-packages/sqlalchemy/orm/persistence.py", line 173, in _bulk_update
    _emit_update_statements(
  File "/opt/anaconda3/lib/python3.8/site-packages/sqlalchemy/orm/persistence.py", line 1025, in _emit_update_statements
    raise orm_exc.StaleDataError(
sqlalchemy.orm.exc.StaleDataError: UPDATE statement on table 'task' expected to update 1 row(s); 0 were matched.
2021-07-19 09:00:08.736 database_manager:604 [ERROR] [MainThread 4545093120] Got exception when trying to insert to table task
Traceback (most recent call last):
  File "/opt/anaconda3/lib/python3.8/site-packages/sqlalchemy/engine/base.py", line 1256, in _execute_context
    self.dialect.do_executemany(
  File "/opt/anaconda3/lib/python3.8/site-packages/sqlalchemy/engine/default.py", line 605, in do_executemany
    cursor.executemany(statement, parameters)
sqlite3.IntegrityError: NOT NULL constraint failed: task.task_fail_cost

The above exception was the direct cause of the following exception:

Traceback (most recent call last):
  File "/opt/anaconda3/lib/python3.8/site-packages/parsl/monitoring/db_manager.py", line 589, in _insert
    self.db.insert(table=table, messages=messages)
  File "/opt/anaconda3/lib/python3.8/site-packages/parsl/monitoring/db_manager.py", line 89, in insert
    self.session.bulk_insert_mappings(mapper, mappings)
  File "/opt/anaconda3/lib/python3.8/site-packages/sqlalchemy/orm/session.py", line 2880, in bulk_insert_mappings
    self._bulk_save_mappings(
  File "/opt/anaconda3/lib/python3.8/site-packages/sqlalchemy/orm/session.py", line 2979, in _bulk_save_mappings
    transaction.rollback(_capture_exception=True)
  File "/opt/anaconda3/lib/python3.8/site-packages/sqlalchemy/util/langhelpers.py", line 68, in __exit__
    compat.raise_(
  File "/opt/anaconda3/lib/python3.8/site-packages/sqlalchemy/util/compat.py", line 182, in raise_
    raise exception
  File "/opt/anaconda3/lib/python3.8/site-packages/sqlalchemy/orm/session.py", line 2967, in _bulk_save_mappings
    persistence._bulk_insert(
  File "/opt/anaconda3/lib/python3.8/site-packages/sqlalchemy/orm/persistence.py", line 95, in _bulk_insert
    _emit_insert_statements(
  File "/opt/anaconda3/lib/python3.8/site-packages/sqlalchemy/orm/persistence.py", line 1083, in _emit_insert_statements
    c = cached_connections[connection].execute(statement, multiparams)
  File "/opt/anaconda3/lib/python3.8/site-packages/sqlalchemy/engine/base.py", line 1011, in execute
    return meth(self, multiparams, params)
  File "/opt/anaconda3/lib/python3.8/site-packages/sqlalchemy/sql/elements.py", line 298, in _execute_on_connection
    return connection._execute_clauseelement(self, multiparams, params)
  File "/opt/anaconda3/lib/python3.8/site-packages/sqlalchemy/engine/base.py", line 1124, in _execute_clauseelement
    ret = self._execute_context(
  File "/opt/anaconda3/lib/python3.8/site-packages/sqlalchemy/engine/base.py", line 1316, in _execute_context
    self._handle_dbapi_exception(
  File "/opt/anaconda3/lib/python3.8/site-packages/sqlalchemy/engine/base.py", line 1510, in _handle_dbapi_exception
    util.raise_(
  File "/opt/anaconda3/lib/python3.8/site-packages/sqlalchemy/util/compat.py", line 182, in raise_
    raise exception
  File "/opt/anaconda3/lib/python3.8/site-packages/sqlalchemy/engine/base.py", line 1256, in _execute_context
    self.dialect.do_executemany(
  File "/opt/anaconda3/lib/python3.8/site-packages/sqlalchemy/engine/default.py", line 605, in do_executemany
    cursor.executemany(statement, parameters)
sqlalchemy.exc.IntegrityError: (sqlite3.IntegrityError) NOT NULL constraint failed: task.task_fail_cost
[SQL: INSERT INTO task (task_id, run_id, task_depends, task_func_name, task_memoize, task_inputs, task_outputs, task_time_invoked, task_fail_count) VALUES (?, ?, ?, ?, ?, ?, ?, ?, ?)]
[parameters: ((1, '56acd361-53d9-4fc2-a6c5-588f15bc9539', '', 'app_A', False, 'None', 'None', '2021-07-19 09:00:08.371504', 0), (2, '56acd361-53d9-4fc2-a6c5-588f15bc9539', '', 'app_B', False, 'None', 'None', '2021-07-19 09:00:08.378491', 0), (3, '56acd361-53d9-4fc2-a6c5-588f15bc9539', '1,2', 'app_C', False, 'None', 'None', '2021-07-19 09:00:08.381572', 0), (4, '56acd361-53d9-4fc2-a6c5-588f15bc9539', '3', 'app_D', False, 'None', 'None', '2021-07-19 09:00:08.382453', 0), (5, '56acd361-53d9-4fc2-a6c5-588f15bc9539', '4', 'app_E', False, 'None', 'None', '2021-07-19 09:00:08.383549', 0))]
(Background on this error at: http://sqlalche.me/e/13/gkpj)
2021-07-19 09:00:08.741 database_manager:578 [ERROR] [MainThread 4545093120] Got exception when trying to update table task
Traceback (most recent call last):
  File "/opt/anaconda3/lib/python3.8/site-packages/parsl/monitoring/db_manager.py", line 559, in _update
    self.db.update(table=table, columns=columns, messages=messages)
  File "/opt/anaconda3/lib/python3.8/site-packages/parsl/monitoring/db_manager.py", line 82, in update
    self.session.bulk_update_mappings(mapper, mappings)
  File "/opt/anaconda3/lib/python3.8/site-packages/sqlalchemy/orm/session.py", line 2939, in bulk_update_mappings
    self._bulk_save_mappings(
  File "/opt/anaconda3/lib/python3.8/site-packages/sqlalchemy/orm/session.py", line 2979, in _bulk_save_mappings
    transaction.rollback(_capture_exception=True)
  File "/opt/anaconda3/lib/python3.8/site-packages/sqlalchemy/util/langhelpers.py", line 68, in __exit__
    compat.raise_(
  File "/opt/anaconda3/lib/python3.8/site-packages/sqlalchemy/util/compat.py", line 182, in raise_
    raise exception
  File "/opt/anaconda3/lib/python3.8/site-packages/sqlalchemy/orm/session.py", line 2959, in _bulk_save_mappings
    persistence._bulk_update(
  File "/opt/anaconda3/lib/python3.8/site-packages/sqlalchemy/orm/persistence.py", line 173, in _bulk_update
    _emit_update_statements(
  File "/opt/anaconda3/lib/python3.8/site-packages/sqlalchemy/orm/persistence.py", line 1025, in _emit_update_statements
    raise orm_exc.StaleDataError(
sqlalchemy.orm.exc.StaleDataError: UPDATE statement on table 'task' expected to update 6 row(s); 0 were matched.
2021-07-19 09:00:09.484 database_manager:604 [ERROR] [MainThread 4545093120] Got exception when trying to insert to table task
Traceback (most recent call last):
  File "/opt/anaconda3/lib/python3.8/site-packages/sqlalchemy/engine/base.py", line 1256, in _execute_context
    self.dialect.do_executemany(
  File "/opt/anaconda3/lib/python3.8/site-packages/sqlalchemy/engine/default.py", line 605, in do_executemany
    cursor.executemany(statement, parameters)
sqlite3.IntegrityError: NOT NULL constraint failed: task.task_fail_cost

The above exception was the direct cause of the following exception:

Traceback (most recent call last):
  File "/opt/anaconda3/lib/python3.8/site-packages/parsl/monitoring/db_manager.py", line 589, in _insert
    self.db.insert(table=table, messages=messages)
  File "/opt/anaconda3/lib/python3.8/site-packages/parsl/monitoring/db_manager.py", line 89, in insert
    self.session.bulk_insert_mappings(mapper, mappings)
  File "/opt/anaconda3/lib/python3.8/site-packages/sqlalchemy/orm/session.py", line 2880, in bulk_insert_mappings
    self._bulk_save_mappings(
  File "/opt/anaconda3/lib/python3.8/site-packages/sqlalchemy/orm/session.py", line 2979, in _bulk_save_mappings
    transaction.rollback(_capture_exception=True)
  File "/opt/anaconda3/lib/python3.8/site-packages/sqlalchemy/util/langhelpers.py", line 68, in __exit__
    compat.raise_(
  File "/opt/anaconda3/lib/python3.8/site-packages/sqlalchemy/util/compat.py", line 182, in raise_
    raise exception
  File "/opt/anaconda3/lib/python3.8/site-packages/sqlalchemy/orm/session.py", line 2967, in _bulk_save_mappings
    persistence._bulk_insert(
  File "/opt/anaconda3/lib/python3.8/site-packages/sqlalchemy/orm/persistence.py", line 95, in _bulk_insert
    _emit_insert_statements(
  File "/opt/anaconda3/lib/python3.8/site-packages/sqlalchemy/orm/persistence.py", line 1083, in _emit_insert_statements
    c = cached_connections[connection].execute(statement, multiparams)
  File "/opt/anaconda3/lib/python3.8/site-packages/sqlalchemy/engine/base.py", line 1011, in execute
    return meth(self, multiparams, params)
  File "/opt/anaconda3/lib/python3.8/site-packages/sqlalchemy/sql/elements.py", line 298, in _execute_on_connection
    return connection._execute_clauseelement(self, multiparams, params)
  File "/opt/anaconda3/lib/python3.8/site-packages/sqlalchemy/engine/base.py", line 1124, in _execute_clauseelement
    ret = self._execute_context(
  File "/opt/anaconda3/lib/python3.8/site-packages/sqlalchemy/engine/base.py", line 1316, in _execute_context
    self._handle_dbapi_exception(
  File "/opt/anaconda3/lib/python3.8/site-packages/sqlalchemy/engine/base.py", line 1510, in _handle_dbapi_exception
    util.raise_(
  File "/opt/anaconda3/lib/python3.8/site-packages/sqlalchemy/util/compat.py", line 182, in raise_
    raise exception
  File "/opt/anaconda3/lib/python3.8/site-packages/sqlalchemy/engine/base.py", line 1256, in _execute_context
    self.dialect.do_executemany(
  File "/opt/anaconda3/lib/python3.8/site-packages/sqlalchemy/engine/default.py", line 605, in do_executemany
    cursor.executemany(statement, parameters)
sqlalchemy.exc.IntegrityError: (sqlite3.IntegrityError) NOT NULL constraint failed: task.task_fail_cost
[SQL: INSERT INTO task (task_id, run_id, task_depends, task_func_name, task_memoize, task_inputs, task_outputs, task_time_invoked, task_fail_count) VALUES (?, ?, ?, ?, ?, ?, ?, ?, ?)]
[parameters: ((6, '56acd361-53d9-4fc2-a6c5-588f15bc9539', '', 'app_A', False, 'None', 'None', '2021-07-19 09:00:09.099954', 0), (7, '56acd361-53d9-4fc2-a6c5-588f15bc9539', '', 'app_B', False, 'None', 'None', '2021-07-19 09:00:09.104291', 0), (8, '56acd361-53d9-4fc2-a6c5-588f15bc9539', '6,7', 'app_C', False, 'None', 'None', '2021-07-19 09:00:09.107090', 0), (9, '56acd361-53d9-4fc2-a6c5-588f15bc9539', '8', 'app_D', False, 'None', 'None', '2021-07-19 09:00:09.108056', 0), (10, '56acd361-53d9-4fc2-a6c5-588f15bc9539', '9', 'app_E', False, 'None', 'None', '2021-07-19 09:00:09.108809', 0))]
(Background on this error at: http://sqlalche.me/e/13/gkpj)
2021-07-19 09:00:09.488 database_manager:578 [ERROR] [MainThread 4545093120] Got exception when trying to update table task
Traceback (most recent call last):
  File "/opt/anaconda3/lib/python3.8/site-packages/parsl/monitoring/db_manager.py", line 559, in _update
    self.db.update(table=table, columns=columns, messages=messages)
  File "/opt/anaconda3/lib/python3.8/site-packages/parsl/monitoring/db_manager.py", line 82, in update
    self.session.bulk_update_mappings(mapper, mappings)
  File "/opt/anaconda3/lib/python3.8/site-packages/sqlalchemy/orm/session.py", line 2939, in bulk_update_mappings
    self._bulk_save_mappings(
  File "/opt/anaconda3/lib/python3.8/site-packages/sqlalchemy/orm/session.py", line 2979, in _bulk_save_mappings
    transaction.rollback(_capture_exception=True)
  File "/opt/anaconda3/lib/python3.8/site-packages/sqlalchemy/util/langhelpers.py", line 68, in __exit__
    compat.raise_(
  File "/opt/anaconda3/lib/python3.8/site-packages/sqlalchemy/util/compat.py", line 182, in raise_
    raise exception
  File "/opt/anaconda3/lib/python3.8/site-packages/sqlalchemy/orm/session.py", line 2959, in _bulk_save_mappings
    persistence._bulk_update(
  File "/opt/anaconda3/lib/python3.8/site-packages/sqlalchemy/orm/persistence.py", line 173, in _bulk_update
    _emit_update_statements(
  File "/opt/anaconda3/lib/python3.8/site-packages/sqlalchemy/orm/persistence.py", line 1025, in _emit_update_statements
    raise orm_exc.StaleDataError(
sqlalchemy.orm.exc.StaleDataError: UPDATE statement on table 'task' expected to update 10 row(s); 0 were matched.
2021-07-19 09:00:09.926 database_manager:578 [ERROR] [MainThread 4545093120] Got exception when trying to update table task
Traceback (most recent call last):
  File "/opt/anaconda3/lib/python3.8/site-packages/parsl/monitoring/db_manager.py", line 559, in _update
    self.db.update(table=table, columns=columns, messages=messages)
  File "/opt/anaconda3/lib/python3.8/site-packages/parsl/monitoring/db_manager.py", line 82, in update
    self.session.bulk_update_mappings(mapper, mappings)
  File "/opt/anaconda3/lib/python3.8/site-packages/sqlalchemy/orm/session.py", line 2939, in bulk_update_mappings
    self._bulk_save_mappings(
  File "/opt/anaconda3/lib/python3.8/site-packages/sqlalchemy/orm/session.py", line 2979, in _bulk_save_mappings
    transaction.rollback(_capture_exception=True)
  File "/opt/anaconda3/lib/python3.8/site-packages/sqlalchemy/util/langhelpers.py", line 68, in __exit__
    compat.raise_(
  File "/opt/anaconda3/lib/python3.8/site-packages/sqlalchemy/util/compat.py", line 182, in raise_
    raise exception
  File "/opt/anaconda3/lib/python3.8/site-packages/sqlalchemy/orm/session.py", line 2959, in _bulk_save_mappings
    persistence._bulk_update(
  File "/opt/anaconda3/lib/python3.8/site-packages/sqlalchemy/orm/persistence.py", line 173, in _bulk_update
    _emit_update_statements(
  File "/opt/anaconda3/lib/python3.8/site-packages/sqlalchemy/orm/persistence.py", line 1025, in _emit_update_statements
    raise orm_exc.StaleDataError(
sqlalchemy.orm.exc.StaleDataError: UPDATE statement on table 'task' expected to update 4 row(s); 0 were matched.
2021-07-19 09:00:10.402 database_manager:578 [ERROR] [MainThread 4545093120] Got exception when trying to update table task
Traceback (most recent call last):
  File "/opt/anaconda3/lib/python3.8/site-packages/parsl/monitoring/db_manager.py", line 559, in _update
    self.db.update(table=table, columns=columns, messages=messages)
  File "/opt/anaconda3/lib/python3.8/site-packages/parsl/monitoring/db_manager.py", line 82, in update
    self.session.bulk_update_mappings(mapper, mappings)
  File "/opt/anaconda3/lib/python3.8/site-packages/sqlalchemy/orm/session.py", line 2939, in bulk_update_mappings
    self._bulk_save_mappings(
  File "/opt/anaconda3/lib/python3.8/site-packages/sqlalchemy/orm/session.py", line 2979, in _bulk_save_mappings
    transaction.rollback(_capture_exception=True)
  File "/opt/anaconda3/lib/python3.8/site-packages/sqlalchemy/util/langhelpers.py", line 68, in __exit__
    compat.raise_(
  File "/opt/anaconda3/lib/python3.8/site-packages/sqlalchemy/util/compat.py", line 182, in raise_
    raise exception
  File "/opt/anaconda3/lib/python3.8/site-packages/sqlalchemy/orm/session.py", line 2959, in _bulk_save_mappings
    persistence._bulk_update(
  File "/opt/anaconda3/lib/python3.8/site-packages/sqlalchemy/orm/persistence.py", line 173, in _bulk_update
    _emit_update_statements(
  File "/opt/anaconda3/lib/python3.8/site-packages/sqlalchemy/orm/persistence.py", line 1025, in _emit_update_statements
    raise orm_exc.StaleDataError(
sqlalchemy.orm.exc.StaleDataError: UPDATE statement on table 'task' expected to update 1 row(s); 0 were matched.
2021-07-19 09:00:13.052 database_manager:627 [INFO] [Monitoring-migrate-priority 123145327075328] Database Manager cleanup initiated.
2021-07-19 09:00:13.144 database_manager:672 [INFO] [MainThread 4545093120] End of dbm_starter
