2021-07-16 12:29:48.915 database_manager:661 [INFO] [MainThread 4765244928] Starting dbm in dbm starter
2021-07-16 12:29:48.916 database_manager:523 [INFO] [Monitoring-migrate-priority 123145412259840] Starting processing for queue priority
2021-07-16 12:29:48.916 database_manager:523 [INFO] [Monitoring-migrate-node 123145429049344] Starting processing for queue node
2021-07-16 12:29:48.917 database_manager:523 [INFO] [Monitoring-migrate-block 123145445838848] Starting processing for queue block
2021-07-16 12:29:48.917 database_manager:523 [INFO] [Monitoring-migrate-resource 123145462628352] Starting processing for queue resource
2021-07-16 12:29:49.441 database_manager:604 [ERROR] [MainThread 4765244928] Got exception when trying to insert to table task
Traceback (most recent call last):
  File "/opt/anaconda3/lib/python3.8/site-packages/sqlalchemy/engine/base.py", line 1276, in _execute_context
    self.dialect.do_execute(
  File "/opt/anaconda3/lib/python3.8/site-packages/sqlalchemy/engine/default.py", line 608, in do_execute
    cursor.execute(statement, parameters)
sqlite3.IntegrityError: NOT NULL constraint failed: task.task_fail_cost

The above exception was the direct cause of the following exception:

Traceback (most recent call last):
  File "/opt/anaconda3/lib/python3.8/site-packages/parsl/monitoring/db_manager.py", line 589, in _insert
    self.db.insert(table=table, messages=messages)
  File "/opt/anaconda3/lib/python3.8/site-packages/parsl/monitoring/db_manager.py", line 89, in insert
    self.session.bulk_insert_mappings(mapper, mappings)
  File "/opt/anaconda3/lib/python3.8/site-packages/sqlalchemy/orm/session.py", line 2880, in bulk_insert_mappings
    self._bulk_save_mappings(
  File "/opt/anaconda3/lib/python3.8/site-packages/sqlalchemy/orm/session.py", line 2979, in _bulk_save_mappings
    transaction.rollback(_capture_exception=True)
  File "/opt/anaconda3/lib/python3.8/site-packages/sqlalchemy/util/langhelpers.py", line 68, in __exit__
    compat.raise_(
  File "/opt/anaconda3/lib/python3.8/site-packages/sqlalchemy/util/compat.py", line 182, in raise_
    raise exception
  File "/opt/anaconda3/lib/python3.8/site-packages/sqlalchemy/orm/session.py", line 2967, in _bulk_save_mappings
    persistence._bulk_insert(
  File "/opt/anaconda3/lib/python3.8/site-packages/sqlalchemy/orm/persistence.py", line 95, in _bulk_insert
    _emit_insert_statements(
  File "/opt/anaconda3/lib/python3.8/site-packages/sqlalchemy/orm/persistence.py", line 1083, in _emit_insert_statements
    c = cached_connections[connection].execute(statement, multiparams)
  File "/opt/anaconda3/lib/python3.8/site-packages/sqlalchemy/engine/base.py", line 1011, in execute
    return meth(self, multiparams, params)
  File "/opt/anaconda3/lib/python3.8/site-packages/sqlalchemy/sql/elements.py", line 298, in _execute_on_connection
    return connection._execute_clauseelement(self, multiparams, params)
  File "/opt/anaconda3/lib/python3.8/site-packages/sqlalchemy/engine/base.py", line 1124, in _execute_clauseelement
    ret = self._execute_context(
  File "/opt/anaconda3/lib/python3.8/site-packages/sqlalchemy/engine/base.py", line 1316, in _execute_context
    self._handle_dbapi_exception(
  File "/opt/anaconda3/lib/python3.8/site-packages/sqlalchemy/engine/base.py", line 1510, in _handle_dbapi_exception
    util.raise_(
  File "/opt/anaconda3/lib/python3.8/site-packages/sqlalchemy/util/compat.py", line 182, in raise_
    raise exception
  File "/opt/anaconda3/lib/python3.8/site-packages/sqlalchemy/engine/base.py", line 1276, in _execute_context
    self.dialect.do_execute(
  File "/opt/anaconda3/lib/python3.8/site-packages/sqlalchemy/engine/default.py", line 608, in do_execute
    cursor.execute(statement, parameters)
sqlalchemy.exc.IntegrityError: (sqlite3.IntegrityError) NOT NULL constraint failed: task.task_fail_cost
[SQL: INSERT INTO task (task_id, run_id, task_depends, task_func_name, task_memoize, task_inputs, task_outputs, task_time_invoked, task_fail_count) VALUES (?, ?, ?, ?, ?, ?, ?, ?, ?)]
[parameters: (0, '53009e3f-fed3-4112-9578-8416901416fa', '', 'app_F', False, 'None', 'None', '2021-07-16 12:29:49.066906', 0)]
(Background on this error at: http://sqlalche.me/e/13/gkpj)
2021-07-16 12:29:49.465 database_manager:578 [ERROR] [MainThread 4765244928] Got exception when trying to update table task
Traceback (most recent call last):
  File "/opt/anaconda3/lib/python3.8/site-packages/parsl/monitoring/db_manager.py", line 559, in _update
    self.db.update(table=table, columns=columns, messages=messages)
  File "/opt/anaconda3/lib/python3.8/site-packages/parsl/monitoring/db_manager.py", line 82, in update
    self.session.bulk_update_mappings(mapper, mappings)
  File "/opt/anaconda3/lib/python3.8/site-packages/sqlalchemy/orm/session.py", line 2939, in bulk_update_mappings
    self._bulk_save_mappings(
  File "/opt/anaconda3/lib/python3.8/site-packages/sqlalchemy/orm/session.py", line 2979, in _bulk_save_mappings
    transaction.rollback(_capture_exception=True)
  File "/opt/anaconda3/lib/python3.8/site-packages/sqlalchemy/util/langhelpers.py", line 68, in __exit__
    compat.raise_(
  File "/opt/anaconda3/lib/python3.8/site-packages/sqlalchemy/util/compat.py", line 182, in raise_
    raise exception
  File "/opt/anaconda3/lib/python3.8/site-packages/sqlalchemy/orm/session.py", line 2959, in _bulk_save_mappings
    persistence._bulk_update(
  File "/opt/anaconda3/lib/python3.8/site-packages/sqlalchemy/orm/persistence.py", line 173, in _bulk_update
    _emit_update_statements(
  File "/opt/anaconda3/lib/python3.8/site-packages/sqlalchemy/orm/persistence.py", line 1025, in _emit_update_statements
    raise orm_exc.StaleDataError(
sqlalchemy.orm.exc.StaleDataError: UPDATE statement on table 'task' expected to update 1 row(s); 0 were matched.
2021-07-16 12:29:51.659 database_manager:604 [ERROR] [MainThread 4765244928] Got exception when trying to insert to table task
Traceback (most recent call last):
  File "/opt/anaconda3/lib/python3.8/site-packages/sqlalchemy/engine/base.py", line 1256, in _execute_context
    self.dialect.do_executemany(
  File "/opt/anaconda3/lib/python3.8/site-packages/sqlalchemy/engine/default.py", line 605, in do_executemany
    cursor.executemany(statement, parameters)
sqlite3.IntegrityError: NOT NULL constraint failed: task.task_fail_cost

The above exception was the direct cause of the following exception:

Traceback (most recent call last):
  File "/opt/anaconda3/lib/python3.8/site-packages/parsl/monitoring/db_manager.py", line 589, in _insert
    self.db.insert(table=table, messages=messages)
  File "/opt/anaconda3/lib/python3.8/site-packages/parsl/monitoring/db_manager.py", line 89, in insert
    self.session.bulk_insert_mappings(mapper, mappings)
  File "/opt/anaconda3/lib/python3.8/site-packages/sqlalchemy/orm/session.py", line 2880, in bulk_insert_mappings
    self._bulk_save_mappings(
  File "/opt/anaconda3/lib/python3.8/site-packages/sqlalchemy/orm/session.py", line 2979, in _bulk_save_mappings
    transaction.rollback(_capture_exception=True)
  File "/opt/anaconda3/lib/python3.8/site-packages/sqlalchemy/util/langhelpers.py", line 68, in __exit__
    compat.raise_(
  File "/opt/anaconda3/lib/python3.8/site-packages/sqlalchemy/util/compat.py", line 182, in raise_
    raise exception
  File "/opt/anaconda3/lib/python3.8/site-packages/sqlalchemy/orm/session.py", line 2967, in _bulk_save_mappings
    persistence._bulk_insert(
  File "/opt/anaconda3/lib/python3.8/site-packages/sqlalchemy/orm/persistence.py", line 95, in _bulk_insert
    _emit_insert_statements(
  File "/opt/anaconda3/lib/python3.8/site-packages/sqlalchemy/orm/persistence.py", line 1083, in _emit_insert_statements
    c = cached_connections[connection].execute(statement, multiparams)
  File "/opt/anaconda3/lib/python3.8/site-packages/sqlalchemy/engine/base.py", line 1011, in execute
    return meth(self, multiparams, params)
  File "/opt/anaconda3/lib/python3.8/site-packages/sqlalchemy/sql/elements.py", line 298, in _execute_on_connection
    return connection._execute_clauseelement(self, multiparams, params)
  File "/opt/anaconda3/lib/python3.8/site-packages/sqlalchemy/engine/base.py", line 1124, in _execute_clauseelement
    ret = self._execute_context(
  File "/opt/anaconda3/lib/python3.8/site-packages/sqlalchemy/engine/base.py", line 1316, in _execute_context
    self._handle_dbapi_exception(
  File "/opt/anaconda3/lib/python3.8/site-packages/sqlalchemy/engine/base.py", line 1510, in _handle_dbapi_exception
    util.raise_(
  File "/opt/anaconda3/lib/python3.8/site-packages/sqlalchemy/util/compat.py", line 182, in raise_
    raise exception
  File "/opt/anaconda3/lib/python3.8/site-packages/sqlalchemy/engine/base.py", line 1256, in _execute_context
    self.dialect.do_executemany(
  File "/opt/anaconda3/lib/python3.8/site-packages/sqlalchemy/engine/default.py", line 605, in do_executemany
    cursor.executemany(statement, parameters)
sqlalchemy.exc.IntegrityError: (sqlite3.IntegrityError) NOT NULL constraint failed: task.task_fail_cost
[SQL: INSERT INTO task (task_id, run_id, task_depends, task_func_name, task_memoize, task_inputs, task_outputs, task_time_invoked, task_fail_count) VALUES (?, ?, ?, ?, ?, ?, ?, ?, ?)]
[parameters: ((1, '53009e3f-fed3-4112-9578-8416901416fa', '', 'app_A', False, 'None', 'None', '2021-07-16 12:29:51.266728', 0), (2, '53009e3f-fed3-4112-9578-8416901416fa', '', 'app_B', False, 'None', 'None', '2021-07-16 12:29:51.274227', 0), (3, '53009e3f-fed3-4112-9578-8416901416fa', '1,2', 'app_C', False, 'None', 'None', '2021-07-16 12:29:51.279011', 0), (4, '53009e3f-fed3-4112-9578-8416901416fa', '3', 'app_D', False, 'None', 'None', '2021-07-16 12:29:51.279871', 0), (5, '53009e3f-fed3-4112-9578-8416901416fa', '4', 'app_E', False, 'None', 'None', '2021-07-16 12:29:51.280630', 0))]
(Background on this error at: http://sqlalche.me/e/13/gkpj)
2021-07-16 12:29:51.663 database_manager:578 [ERROR] [MainThread 4765244928] Got exception when trying to update table task
Traceback (most recent call last):
  File "/opt/anaconda3/lib/python3.8/site-packages/parsl/monitoring/db_manager.py", line 559, in _update
    self.db.update(table=table, columns=columns, messages=messages)
  File "/opt/anaconda3/lib/python3.8/site-packages/parsl/monitoring/db_manager.py", line 82, in update
    self.session.bulk_update_mappings(mapper, mappings)
  File "/opt/anaconda3/lib/python3.8/site-packages/sqlalchemy/orm/session.py", line 2939, in bulk_update_mappings
    self._bulk_save_mappings(
  File "/opt/anaconda3/lib/python3.8/site-packages/sqlalchemy/orm/session.py", line 2979, in _bulk_save_mappings
    transaction.rollback(_capture_exception=True)
  File "/opt/anaconda3/lib/python3.8/site-packages/sqlalchemy/util/langhelpers.py", line 68, in __exit__
    compat.raise_(
  File "/opt/anaconda3/lib/python3.8/site-packages/sqlalchemy/util/compat.py", line 182, in raise_
    raise exception
  File "/opt/anaconda3/lib/python3.8/site-packages/sqlalchemy/orm/session.py", line 2959, in _bulk_save_mappings
    persistence._bulk_update(
  File "/opt/anaconda3/lib/python3.8/site-packages/sqlalchemy/orm/persistence.py", line 173, in _bulk_update
    _emit_update_statements(
  File "/opt/anaconda3/lib/python3.8/site-packages/sqlalchemy/orm/persistence.py", line 1025, in _emit_update_statements
    raise orm_exc.StaleDataError(
sqlalchemy.orm.exc.StaleDataError: UPDATE statement on table 'task' expected to update 6 row(s); 0 were matched.
2021-07-16 12:29:52.102 database_manager:578 [ERROR] [MainThread 4765244928] Got exception when trying to update table task
Traceback (most recent call last):
  File "/opt/anaconda3/lib/python3.8/site-packages/parsl/monitoring/db_manager.py", line 559, in _update
    self.db.update(table=table, columns=columns, messages=messages)
  File "/opt/anaconda3/lib/python3.8/site-packages/parsl/monitoring/db_manager.py", line 82, in update
    self.session.bulk_update_mappings(mapper, mappings)
  File "/opt/anaconda3/lib/python3.8/site-packages/sqlalchemy/orm/session.py", line 2939, in bulk_update_mappings
    self._bulk_save_mappings(
  File "/opt/anaconda3/lib/python3.8/site-packages/sqlalchemy/orm/session.py", line 2979, in _bulk_save_mappings
    transaction.rollback(_capture_exception=True)
  File "/opt/anaconda3/lib/python3.8/site-packages/sqlalchemy/util/langhelpers.py", line 68, in __exit__
    compat.raise_(
  File "/opt/anaconda3/lib/python3.8/site-packages/sqlalchemy/util/compat.py", line 182, in raise_
    raise exception
  File "/opt/anaconda3/lib/python3.8/site-packages/sqlalchemy/orm/session.py", line 2959, in _bulk_save_mappings
    persistence._bulk_update(
  File "/opt/anaconda3/lib/python3.8/site-packages/sqlalchemy/orm/persistence.py", line 173, in _bulk_update
    _emit_update_statements(
  File "/opt/anaconda3/lib/python3.8/site-packages/sqlalchemy/orm/persistence.py", line 1025, in _emit_update_statements
    raise orm_exc.StaleDataError(
sqlalchemy.orm.exc.StaleDataError: UPDATE statement on table 'task' expected to update 4 row(s); 0 were matched.
2021-07-16 12:29:52.533 database_manager:604 [ERROR] [MainThread 4765244928] Got exception when trying to insert to table task
Traceback (most recent call last):
  File "/opt/anaconda3/lib/python3.8/site-packages/sqlalchemy/engine/base.py", line 1256, in _execute_context
    self.dialect.do_executemany(
  File "/opt/anaconda3/lib/python3.8/site-packages/sqlalchemy/engine/default.py", line 605, in do_executemany
    cursor.executemany(statement, parameters)
sqlite3.IntegrityError: NOT NULL constraint failed: task.task_fail_cost

The above exception was the direct cause of the following exception:

Traceback (most recent call last):
  File "/opt/anaconda3/lib/python3.8/site-packages/parsl/monitoring/db_manager.py", line 589, in _insert
    self.db.insert(table=table, messages=messages)
  File "/opt/anaconda3/lib/python3.8/site-packages/parsl/monitoring/db_manager.py", line 89, in insert
    self.session.bulk_insert_mappings(mapper, mappings)
  File "/opt/anaconda3/lib/python3.8/site-packages/sqlalchemy/orm/session.py", line 2880, in bulk_insert_mappings
    self._bulk_save_mappings(
  File "/opt/anaconda3/lib/python3.8/site-packages/sqlalchemy/orm/session.py", line 2979, in _bulk_save_mappings
    transaction.rollback(_capture_exception=True)
  File "/opt/anaconda3/lib/python3.8/site-packages/sqlalchemy/util/langhelpers.py", line 68, in __exit__
    compat.raise_(
  File "/opt/anaconda3/lib/python3.8/site-packages/sqlalchemy/util/compat.py", line 182, in raise_
    raise exception
  File "/opt/anaconda3/lib/python3.8/site-packages/sqlalchemy/orm/session.py", line 2967, in _bulk_save_mappings
    persistence._bulk_insert(
  File "/opt/anaconda3/lib/python3.8/site-packages/sqlalchemy/orm/persistence.py", line 95, in _bulk_insert
    _emit_insert_statements(
  File "/opt/anaconda3/lib/python3.8/site-packages/sqlalchemy/orm/persistence.py", line 1083, in _emit_insert_statements
    c = cached_connections[connection].execute(statement, multiparams)
  File "/opt/anaconda3/lib/python3.8/site-packages/sqlalchemy/engine/base.py", line 1011, in execute
    return meth(self, multiparams, params)
  File "/opt/anaconda3/lib/python3.8/site-packages/sqlalchemy/sql/elements.py", line 298, in _execute_on_connection
    return connection._execute_clauseelement(self, multiparams, params)
  File "/opt/anaconda3/lib/python3.8/site-packages/sqlalchemy/engine/base.py", line 1124, in _execute_clauseelement
    ret = self._execute_context(
  File "/opt/anaconda3/lib/python3.8/site-packages/sqlalchemy/engine/base.py", line 1316, in _execute_context
    self._handle_dbapi_exception(
  File "/opt/anaconda3/lib/python3.8/site-packages/sqlalchemy/engine/base.py", line 1510, in _handle_dbapi_exception
    util.raise_(
  File "/opt/anaconda3/lib/python3.8/site-packages/sqlalchemy/util/compat.py", line 182, in raise_
    raise exception
  File "/opt/anaconda3/lib/python3.8/site-packages/sqlalchemy/engine/base.py", line 1256, in _execute_context
    self.dialect.do_executemany(
  File "/opt/anaconda3/lib/python3.8/site-packages/sqlalchemy/engine/default.py", line 605, in do_executemany
    cursor.executemany(statement, parameters)
sqlalchemy.exc.IntegrityError: (sqlite3.IntegrityError) NOT NULL constraint failed: task.task_fail_cost
[SQL: INSERT INTO task (task_id, run_id, task_depends, task_func_name, task_memoize, task_inputs, task_outputs, task_time_invoked, task_fail_count) VALUES (?, ?, ?, ?, ?, ?, ?, ?, ?)]
[parameters: ((6, '53009e3f-fed3-4112-9578-8416901416fa', '', 'app_A', False, 'None', 'None', '2021-07-16 12:29:52.105400', 0), (7, '53009e3f-fed3-4112-9578-8416901416fa', '', 'app_B', False, 'None', 'None', '2021-07-16 12:29:52.112119', 0), (8, '53009e3f-fed3-4112-9578-8416901416fa', '6,7', 'app_C', False, 'None', 'None', '2021-07-16 12:29:52.115476', 0), (9, '53009e3f-fed3-4112-9578-8416901416fa', '8', 'app_D', False, 'None', 'None', '2021-07-16 12:29:52.116508', 0), (10, '53009e3f-fed3-4112-9578-8416901416fa', '9', 'app_E', False, 'None', 'None', '2021-07-16 12:29:52.117255', 0))]
(Background on this error at: http://sqlalche.me/e/13/gkpj)
2021-07-16 12:29:52.536 database_manager:578 [ERROR] [MainThread 4765244928] Got exception when trying to update table task
Traceback (most recent call last):
  File "/opt/anaconda3/lib/python3.8/site-packages/parsl/monitoring/db_manager.py", line 559, in _update
    self.db.update(table=table, columns=columns, messages=messages)
  File "/opt/anaconda3/lib/python3.8/site-packages/parsl/monitoring/db_manager.py", line 82, in update
    self.session.bulk_update_mappings(mapper, mappings)
  File "/opt/anaconda3/lib/python3.8/site-packages/sqlalchemy/orm/session.py", line 2939, in bulk_update_mappings
    self._bulk_save_mappings(
  File "/opt/anaconda3/lib/python3.8/site-packages/sqlalchemy/orm/session.py", line 2979, in _bulk_save_mappings
    transaction.rollback(_capture_exception=True)
  File "/opt/anaconda3/lib/python3.8/site-packages/sqlalchemy/util/langhelpers.py", line 68, in __exit__
    compat.raise_(
  File "/opt/anaconda3/lib/python3.8/site-packages/sqlalchemy/util/compat.py", line 182, in raise_
    raise exception
  File "/opt/anaconda3/lib/python3.8/site-packages/sqlalchemy/orm/session.py", line 2959, in _bulk_save_mappings
    persistence._bulk_update(
  File "/opt/anaconda3/lib/python3.8/site-packages/sqlalchemy/orm/persistence.py", line 173, in _bulk_update
    _emit_update_statements(
  File "/opt/anaconda3/lib/python3.8/site-packages/sqlalchemy/orm/persistence.py", line 1025, in _emit_update_statements
    raise orm_exc.StaleDataError(
sqlalchemy.orm.exc.StaleDataError: UPDATE statement on table 'task' expected to update 6 row(s); 0 were matched.
2021-07-16 12:29:53.133 database_manager:578 [ERROR] [MainThread 4765244928] Got exception when trying to update table task
Traceback (most recent call last):
  File "/opt/anaconda3/lib/python3.8/site-packages/parsl/monitoring/db_manager.py", line 559, in _update
    self.db.update(table=table, columns=columns, messages=messages)
  File "/opt/anaconda3/lib/python3.8/site-packages/parsl/monitoring/db_manager.py", line 82, in update
    self.session.bulk_update_mappings(mapper, mappings)
  File "/opt/anaconda3/lib/python3.8/site-packages/sqlalchemy/orm/session.py", line 2939, in bulk_update_mappings
    self._bulk_save_mappings(
  File "/opt/anaconda3/lib/python3.8/site-packages/sqlalchemy/orm/session.py", line 2979, in _bulk_save_mappings
    transaction.rollback(_capture_exception=True)
  File "/opt/anaconda3/lib/python3.8/site-packages/sqlalchemy/util/langhelpers.py", line 68, in __exit__
    compat.raise_(
  File "/opt/anaconda3/lib/python3.8/site-packages/sqlalchemy/util/compat.py", line 182, in raise_
    raise exception
  File "/opt/anaconda3/lib/python3.8/site-packages/sqlalchemy/orm/session.py", line 2959, in _bulk_save_mappings
    persistence._bulk_update(
  File "/opt/anaconda3/lib/python3.8/site-packages/sqlalchemy/orm/persistence.py", line 173, in _bulk_update
    _emit_update_statements(
  File "/opt/anaconda3/lib/python3.8/site-packages/sqlalchemy/orm/persistence.py", line 1025, in _emit_update_statements
    raise orm_exc.StaleDataError(
sqlalchemy.orm.exc.StaleDataError: UPDATE statement on table 'task' expected to update 5 row(s); 0 were matched.
2021-07-16 12:29:56.041 database_manager:627 [INFO] [Monitoring-migrate-priority 123145412259840] Database Manager cleanup initiated.
2021-07-16 12:29:56.302 database_manager:672 [INFO] [MainThread 4765244928] End of dbm_starter
